# SOME DESCRIPTIVE TITLE.
# Copyright (C) YEAR THE PACKAGE'S COPYRIGHT HOLDER
# This file is distributed under the same license as the PACKAGE package.
#
# Translators:
# gtufano <gt@iltofa.com>, 2014
# luX <lucianocataldo@gmail.com>, 2014
# n.patriarchi <niccolo@cyber.it>, 2014
# umberto <web.af@email.it>, 2013
msgid ""
msgstr ""
"Project-Id-Version: IPFire Project\n"
"Report-Msgid-Bugs-To: \n"
"POT-Creation-Date: 2014-09-29 14:20+0000\n"
"PO-Revision-Date: 2014-09-29 14:25+0000\n"
"Last-Translator: Michael Tremer <michael.tremer@ipfire.org>\n"
"Language-Team: Italian (http://www.transifex.com/projects/p/ipfire/language/"
"it/)\n"
"Language: it\n"
"MIME-Version: 1.0\n"
"Content-Type: text/plain; charset=UTF-8\n"
"Content-Transfer-Encoding: 8bit\n"
"Plural-Forms: nplurals=2; plural=(n != 1);\n"

#: ../src/ddns/__init__.py:63
msgid "Debugging mode enabled"
msgstr "Modalità di debug abilitata"

#: ../src/ddns/__init__.py:90
#, python-format
msgid "Loading configuration file %s"
msgstr "Carico il file di configurazione %s"

#: ../src/ddns/__init__.py:156
msgid "Found no entries in the configuration file. Exiting."
msgstr "Non ha trovato voci nel file di configurazione"

#: ../src/ddns/__init__.py:167
#, python-format
msgid "Dynamic DNS update for %(hostname)s (%(provider)s) failed:"
msgstr "Aggiornamento DNS dinamico fallita per  %(hostname)s (%(provider)s)"

#: ../src/ddns/__init__.py:174
#, python-format
msgid ""
"Dynamic DNS update for %(hostname)s (%(provider)s) throwed an unhandled "
"exception:"
msgstr ""
"Aggiornamento DNS dinamico per  %(hostname)s (%(provider)s) generata "
"un'eccezione non gestita:"

#: ../src/ddns/errors.py:29
msgid "Error"
msgstr "Errore"

#: ../src/ddns/errors.py:39
msgid "Network error"
msgstr "Errore di rete"

#: ../src/ddns/errors.py:47
msgid ""
"The server denied processing the request because account abuse is suspected"
msgstr ""
"Il server non processerà la richiesta perché sospetta un abuso dell'account "
"utente"

#: ../src/ddns/errors.py:55
msgid "Authentication against the server has failed"
msgstr "L'autenticazione sul server è fallita."

#: ../src/ddns/errors.py:64
msgid "The server denies any updates from this client"
msgstr "Il server non vuole aggiornamenti da questo client"

#: ../src/ddns/errors.py:72
msgid "The configuration file has errors"
msgstr "Il file di configurazione ha errori"

#: ../src/ddns/errors.py:79
msgid "Connection refused"
msgstr "Connessione rifiutata"

#: ../src/ddns/errors.py:86 ../src/ddns/system.py:218
msgid "Connection timeout"
msgstr "Connessione scaduta"

#: ../src/ddns/errors.py:94
msgid "The host could not be found in the configuration file"
msgstr "L'host non può essere trovato nel file di configurazione"

#: ../src/ddns/errors.py:102
msgid "Internal server error"
msgstr "Errore interno del server"

#: ../src/ddns/errors.py:109
msgid "Network unreachable"
msgstr "Rete irraggiungibile"

#: ../src/ddns/errors.py:116
#, fuzzy
msgid "Not found"
msgstr "Dominio non trovato."

#: ../src/ddns/errors.py:124
msgid "Request error"
msgstr "Errore nella richiesta"

#: ../src/ddns/errors.py:132
msgid "Could not resolve DNS entry"
msgstr ""

#: ../src/ddns/errors.py:139
msgid "Service unavailable"
msgstr "Serivizio non disponibile"

#: ../src/ddns/errors.py:147
msgid "The update could not be performed"
msgstr "L'aggiornamento non può essere eseguito"

#: ../src/ddns/providers.py:85
msgid "Provider is not properly configured"
msgstr ""

#: ../src/ddns/providers.py:154
#, python-format
msgid "Updating %s forced"
msgstr "L'aggiornamento %s è stato forzato"

#: ../src/ddns/providers.py:170
#, python-format
msgid "Dynamic DNS update for %(hostname)s (%(provider)s) successful"
msgstr ""
"Aggiornamento DNS dinamico per %(hostname)s (%(provider)s) eseguito con "
"successo"

#: ../src/ddns/providers.py:194
#, fuzzy, python-format
msgid ""
"An update for %(hostname)s (%(provider)s) is performed because of an IP "
"address change"
msgstr ""
"Aggiornamento DNS dinamico per  %(hostname)s (%(provider)s) generata "
"un'eccezione non gestita:"

#: ../src/ddns/providers.py:202
#, fuzzy, python-format
msgid ""
"An update for %(hostname)s (%(provider)s) is performed because the holdoff "
"time has expired"
msgstr ""
"Aggiornamento DNS dinamico per  %(hostname)s (%(provider)s) generata "
"un'eccezione non gestita:"

#. Otherwise, we don't need to perform an update
#: ../src/ddns/providers.py:209
#, fuzzy, python-format
msgid "No update required for %(hostname)s (%(provider)s)"
msgstr "Aggiornamento DNS dinamico fallita per  %(hostname)s (%(provider)s)"

#: ../src/ddns/providers.py:228 ../src/ddns/providers.py:242
#, python-format
msgid "An update has not been performed because earlier updates failed for %s"
msgstr ""

#: ../src/ddns/providers.py:230
msgid "There will be no retries"
msgstr ""

#: ../src/ddns/providers.py:246
msgid "Last failure message:"
msgstr ""

#: ../src/ddns/providers.py:251
#, python-format
msgid "Further updates will be withheld until %s"
msgstr ""

#: ../src/ddns/providers.py:385 ../src/ddns/providers.py:612
#: ../src/ddns/providers.py:1191 ../src/ddns/providers.py:1340
msgid "No valid FQDN was given."
msgstr "Non è stato dato un valido FQDN."

#: ../src/ddns/providers.py:387
msgid "Specified host does not exist."
msgstr "L'host specificato non esiste"

#: ../src/ddns/providers.py:391
msgid "DNS error encountered."
msgstr "Errore nel DNS."

#. If we got here, some other update error happened.
#: ../src/ddns/providers.py:396 ../src/ddns/providers.py:785
#, python-format
msgid "Server response: %s"
msgstr "Risposta del server: %s"

#: ../src/ddns/providers.py:531
msgid "Scriptlet:"
msgstr ""

#: ../src/ddns/providers.py:614 ../src/ddns/providers.py:661
msgid "Invalid hostname specified."
msgstr "Nome host specificato non valido."

#: ../src/ddns/providers.py:616
msgid "Hostname not marked as a dynamic host."
msgstr "Il nome host non è marcato come uno dinamico."

#: ../src/ddns/providers.py:618 ../src/ddns/providers.py:670
#: ../src/ddns/providers.py:905
msgid "Invalid IP address has been sent."
msgstr "E' stato inviato un indirizzo IP non valido."

#: ../src/ddns/providers.py:658
msgid "No hostname specified."
msgstr "Nome dell'host non specificato"

#: ../src/ddns/providers.py:667
msgid "Account has been disabled."
msgstr "L'utente è stato disabilitato"

#: ../src/ddns/providers.py:673
msgid "Too many failed requests."
msgstr "Troppe richieste fallite"

#: ../src/ddns/providers.py:776
#, fuzzy
msgid "Malformed request has been sent."
msgstr "E' stato inviato un indirizzo IP non valido."

#: ../src/ddns/providers.py:780
msgid "Too frequent update requests have been sent."
msgstr ""

#: ../src/ddns/providers.py:826 ../src/ddns/providers.py:1013
msgid "Domain not found."
msgstr "Dominio non trovato."

#: ../src/ddns/providers.py:861
#, fuzzy
msgid "An invalid IP address was submitted"
msgstr "E' stato inviato un indirizzo IP non valido."

#: ../src/ddns/providers.py:1015
msgid "Domain not active."
msgstr "Dominio non attivo."

#: ../src/ddns/providers.py:1165
msgid "No Auth details specified."
msgstr "Nessun dettagli di autorizzazione specificato."

#: ../src/ddns/providers.py:1187
msgid "Invalid IPv4 address has been sent."
msgstr "È stato spedito un indirizzo IPv4 non valido."

#: ../src/ddns/providers.py:1189
msgid "Invalid IPv6 address has been sent."
msgstr "È stato spedito un indirizzo IPv6 non valido."

#: ../src/ddns/providers.py:1385
#, fuzzy
msgid "Invalid hostname specified"
msgstr "Nome host specificato non valido."

#: ../src/ddns/system.py:55
#, python-format
msgid "Running on distribution: %s"
msgstr "In esecuzione sulla distribuzione: %s"

#: ../src/ddns/system.py:153
msgid "Request header:"
msgstr "Intestazione di richiesta:"

#. Log response header.
#: ../src/ddns/system.py:161 ../src/ddns/system.py:170
#, python-format
msgid "Response header (Status Code %s):"
msgstr "Testata della risposta (codice di stato %s)."
